Workbook

Sheet Generadores
A2: Obra: | H2: Fecha:
A3: Ubicación: | H3: Hoja No:
A4: CONCEPTO: | B4: TRAZO Y NIVELACIÓN CON NIVELETAS, HILOS Y CAL. INCLUYE; MATERIAL, MANO DE OBRA Y HERRAMIENTA. | H4: TOTAL: | I4: =SUM(H6:H6) -> 34.713
A5: Eje | B5: Tramo | C5: Unidad | D5: Largo | E5: Ancho | F5: Alto | G5: No de Pzas. | H5: Parcial | I5: Observaciones
A6: A-B | B6: 10-17 | C6: M2 | D6: 5.51 | E6: 6.3 | H6: =PRODUCT(D6:G6) -> 34.713
A9: Obra: | H9: Fecha:
A10: Ubicación: | H10: Hoja No:
A11: CONCEPTO: | B11: EXCAVACIÓN POR MEDIOS MECÁNICOS PARA CIMENTACIÓN A UNA PROFUNDIDAD DE 1.35M. INCLUYE; RETROEXCAVADORA Y OPERADOR. | H11: TOTAL: | I11: =SUM(H13:H14) -> 7.182
A12: Eje | B12: Tramo | C12: Unidad | D12: Largo | E12: Ancho | F12: Alto | G12: No de Pzas. | H12: Parcial | I12: Observaciones
A13: A-B | B13: 12-17 | C13: M3 | D13: 2.66 | E13: 1 | F13: 1.35 | G13: 1 | H13: =PRODUCT(D13:G13) -> 3.591
A14: G-H | B14: 12-17 | C14: M3 | D14: 2.66 | E14: 1 | F14: 1.35 | G14: 1 | H14: =PRODUCT(D14:G14) -> 3.591
A16: Obra: | H16: Fecha:
A17: Ubicación: | H17: Hoja No:
A18: CONCEPTO: | B18: EXCAVACIÓN POR MEDIOS MECÁNICOS PARA TRABE DE LIGA PROFUNDIDAD 70CM INCLUYE; RETROEXCAVADORA Y OPERADOR. | H18: TOTAL: | I18: =SUM(H20:H20) -> 0.565
A19: Eje | B19: Tramo | C19: Unidad | D19: Largo | E19: Ancho | F19: Alto | G19: No de Pzas. | H19: Parcial | I19: Observaciones
A20: 17 | B20: A-B | C20: M3 | D20: 0.25 | E20: 5.65 | F20: 0.4 | H20: =PRODUCT(D20:G20) -> 0.565
A23: Obra: | H23: Fecha:
A24: Ubicación: | H24: Hoja No:
A25: CONCEPTO: | B25: AFINE DE EXCAVACIÓN POR MEDIOS MANUALES. INCLUYE; MANO DE OBRA Y HERRAMIENTA. | H25: TOTAL: | I25: =SUM(H27:H28) -> 8.932
A26: Eje | B26: Tramo | C26: Unidad | D26: Largo | E26: Ancho | F26: Alto | G26: No de Pzas. | H26: Parcial | I26: Observaciones
A27: A-B | B27: 12-17 | C27: M3 | D27: 2.66 | E27: 1 | F27: 1.35 | G27: 2 | H27: =PRODUCT(D27:G27) -> 7.182
A28: 17 | B28: A-B | C28: M3 | D28: 0.5 | E28: 5 | F28: 0.7 | H28: =PRODUCT(D28:G28) -> 1.75
A31: Obra: | H31: Fecha:
A32: Ubicación: | H32: Hoja No:
A33: CONCEPTO: | B33: PLANTILLA DE CONCRETO F´c=100 kg/cm2 HECHO EN OBRA DE 5 cm DE ESPESOR. INCLUYE; MATERIAL, MANO DE OBRA Y HERRAMIENTA. | H33: TOTAL: | I33: =SUM(H35:H36) -> 5.32
A34: Eje | B34: Tramo | C34: Unidad | D34: Largo | E34: Ancho | F34: Alto | G34: No de Pzas. | H34: Parcial | I34: Observaciones
A35: A-B | B35: 12-17 | C35: m² | D35: {=D13:E14} -> 2.66 | E35: 1 | H35: =PRODUCT(D35:G35) -> 2.66
A36: A-B | B36: 12-17 | C36: m² | D36: 2.66 | E36: 1 | H36: =PRODUCT(D36:G36) -> 2.66
A39: Obra: | H39: Fecha:
A40: Ubicación: | H40: Hoja No:
A41: CONCEPTO: | B41: ZAPATA CORRIDA DE 1.00m, ESPESOR DE 15 cm EN EL PERIMETRO Y 20 cm AL CENTRO, CONCRETO F´c= 200 kg/cm2, ARMADA CON UNA PARRILLA SENCILLA DE VAR #3 EN DOS DIRECCIONES @ 20 cm. INCLUYE; MATERIAL, CIMBRA Y DESCIMBRA, COLADO, VIBRADO Y CURADO. | H41: TOTAL: | I41: =SUM(H43:H44) -> 1.064
A42: Eje | B42: Tramo | C42: Unidad | D42: Largo | E42: Ancho | F42: Alto | G42: No de Pzas. | H42: Parcial | I42: Observaciones
A43: A | B43: 12-17 | D43: 2.66 | E43: 1 | F43: 0.2 | H43: =PRODUCT(D43:G43) -> 0.532
A44: H | B44: 12-17 | D44: 2.66 | E44: 1 | F44: 0.2 | H44: =PRODUCT(D44:G44) -> 0.532
A47: Obra: | H47: Fecha:
A48: Ubicación: | H48: Hoja No:
A49: CONCEPTO: | B49: DADO DE 0.65 X 0.20 m, CONCRETO F´c=200 kg/cm2, ARMADO CON 4 VAR # 3 Y ESTRIBOS #2 @ 20 cm. INCLUYE; MATERIALES, CIMBRA Y DESCIMBRA, COLADO, MANO DE OBRA, HERRAMIENTA Y EQUIPO. | H49: TOTAL: | I49: =SUM(H51:H51) -> 4.2
A50: Eje | B50: Tramo | C50: Unidad | D50: Largo | E50: Ancho | F50: Alto | G50: No de Pzas. | H50: Parcial | I50: Observaciones
A51: 17 | B51: A,H | C51: ML | F51: 1.05 | G51: 4 | H51: =PRODUCT(D51:G51) -> 4.2
A54: Obra: | H54: Fecha:
...

Sheet Catalogo de conceptos 
C1: CLAVE | D1: DESCRIPCIÓN | E1: UNIDAD | F1: CANTIDAD | G1: CD | H1: IMPORTE DIRECTO | I1: INDIRECTOS | M1: UTILIDAD | Q1: P.U. | R1: IMPORTE
A2: Capítulo | B2: - | C2: &A | D2: PROYECTO ERIK
A3: Subcapítulo | B3: - | C3: #01-000 | D3: PRELIMINARES | H3: =SUM(#REF!) -> #REF! | I3: % | J3: % EN $ | K3: CD+IND | L3: $ | M3: % | N3: % EN $ | O3: CD+IND+UTILIDAD | P3: UTILIDAD EN $ | R3: =SUM(#REF!) -> #REF!
A4: Concepto | C4: 01-001 | D4: TRAZO Y NIVELACIÓN CON NIVELETAS, HILOS Y CAL. INCLUYE; MATERIAL, MANO DE OBRA Y HERRAMIENTA. | E4: m² | F4: =Generadores!I4 -> 34.713
A5: Concepto | C5: 01-002 | D5: DEMOLICION DE PISO EXISTENTE. INCLUYE; MATERIAL, MANO DE OBRA Y HERRAMIENTA. | E5: m²
A6: Concepto | C6: 01-003 | D6: DEMOLICIONDE MARQUESINA EXISTENTE. INCLUYE; MATERIAL, MANO DE OBRA Y HERRAMIENTA. | E6: LOTE
A7: Subcapítulo | B7: - | C7: #02-000 | D7: CIMENTACIÓN
A8: Concepto | C8: 02-001 | D8: EXCAVACIÓN POR MEDIOS MECÁNICOS PARA CIMENTACIÓN A UNA PROFUNDIDAD DE 1.35M. INCLUYE; RETROEXCAVADORA Y OPERADOR. | E8: m³ | F8: =Generadores!I11 -> 7.182
C9: 02-002 | D9: EXCAVACIÓN POR MEDIOS MECÁNICOS PARA TRABE DE LIGA PROFUNDIDAD 1.35CM INCLUYE; RETROEXCAVADORA Y OPERADOR. | E9: m³
A10: Concepto | C10: 02-003 | D10: AFINE DE EXCAVACIÓN POR MEDIOS MANUALES. INCLUYE; MANO DE OBRA Y HERRAMIENTA. | E10: m² | F10: =Generadores!I25 -> 8.932
A11: Concepto | C11: 02-004 | D11: PLANTILLA DE CONCRETO F´c=100 kg/cm2 HECHO EN OBRA DE 5 cm DE ESPESOR. INCLUYE; MATERIAL, MANO DE OBRA Y HERRAMIENTA. | E11: m² | F11: =Generadores!I33 -> 5.32
A12: Concepto | C12: 02-005 | D12: ZAPATA AISLADA DE 1.00 X 1.00, ESPESOR DE 15 cm EN EL PERIMETRO Y 20 cm AL CENTRO, CONCRETO F´c= 200 kg/cm2, ARMADA CON UNA PARRILLA SENCILLA DE VAR #3 EN DOS DIRECCIONES @ 20 cm. INCLUYE; MATERIAL, CIMBRA Y DESCIMBRA, COLADO, VIBRADO Y CURADO. | E12: pza
A13: Concepto | C13: 02-006 | D13: ZAPATA AISLADA DE 1.20 X 1.20, ESPESOR DE 15 cm EN EL PERIMETRO Y 20 cm AL CENTRO, CONCRETO F´c= 200 kg/cm2, ARMADA CON UNA PARRILLA SENCILLA DE VAR #3 EN DOS DIRECCIONES @ 20 cm. INCLUYE; MATERIAL, CIMBRA Y DESCIMBRA, COLADO, VIBRADO Y CURADO. | E13: pza
A14: Concepto | C14: 02-007 | D14: DADO DE 0.20 X 0.20 m, CONCRETO F´c=200 kg/cm2, ARMADO CON 4 VAR # 3 Y ESTRIBOS #2 @ 20 cm. INCLUYE; MATERIALES, CIMBRA Y DESCIMBRA, COLADO, MANO DE OBRA, HERRAMIENTA Y EQUIPO. | E14: ml
A15: Concepto | C15: 02-008 | D15: DADO DE 0.25 X 0.25 m, CONCRETO F´c=200 kg/cm2, ARMADO CON 4 VAR # 4, 2 VAR #3 Y ESTRIBOS #2 @ 20 cm. INCLUYE; MATERIALES, CIMBRA Y DESCIMBRA, COLADO, MANO DE OBRA, HERRAMIENTA Y EQUIPO. | E15: ml
A16: Concepto | C16: 02-009 | D16: SUMINISTRO Y COLOCACIÓN DE IMPERMEABILIZANTE PARA ESTRUCTURAS ENTERRADAS BASE ASFALTO EN ZAPATAS Y DADOS. INCLUYE: MATERIAL, MANO DE OBRA Y HERRAMIENTA. | E16: m² | F16: =Generadores!I64 -> #REF!
C17: 02-010 | D17: SUMINISTRO Y COLOCACIÓN DE IMPERMEABILIZANTE PARA BLOCK ENTERRADO. INCLUYE: MATERIAL, MANO DE OBRA Y HERRAMIENTA. | E17: m²
A18: Concepto | C18: 02-011 | D18: TRABE DE LIGA DE 0.30x0.15 m DE CONCRETO F´c=200 kg/cm2 ARMADA CON 4 VAR #5 Y ESTRIBOS #3 @ 20 cm. INCLUYE; MATERIAL, MANO DE OBRA, HERRAMIENTA Y EQUIPO. | E18: ml | F18: =Generadores!I75 -> 10.3
A19: Concepto | C19: 02-012 | D19: MURO DE BLOCK PARA CIMENTACION. INCLUYE; MATERIAL, MANO DE OBRA, HERRAMIENTA Y EQUIPO. | E19: m² | F19: =Generadores!I56 -> 4.981
A20: Concepto | C20: 02-013 | D20: DALA DE CERRAMIENTO 16 X 22 cm PARA CONFINAR CIMENTACION, REFORZADO CON 4 VAR #3 Y ESTRIBOS #2 @ 20 cm. INCLUYE; MATERIALES, CIMBRA, MANO DE OBRA, HERRAMIENTA Y EQUIUPO. | E20: ml
A21: Concepto | C21: 02-014 | D21: RELLENO Y COMPACTACIÓN CON MATERIAL PRODUCTO DE EXCAVACIÓN EN TRABES DE LIGA. INCLUYE; MANO DE OBRA, HERRAMIENTA Y EQUIPO. | E21: m³
A22: Concepto | C22: 02-015 | D22: CARGA Y RETIRO DE MATERIAL SOBRANTE DE LOS RELLENOS. INCLUYE; RETROEXCAVADORA, CAMION Y OPERADORES. | E22: m³ | F22: =Generadores!I99 -> 0
A23: Subcapítulo | B23: - | C23: #03-000 | D23: MUROS, DALAS Y CASTILLOS PLANTA BAJA
A24: Concepto | C24: 02-012 | D24: MURO DE BLOCK PARA CIMENTACION. INCLUYE; MATERIAL, MANO DE OBRA, HERRAMIENTA Y EQUIPO. | E24: m² | F24: =Generadores!I56 -> 4.981
A25: Concepto | C25: 03-002 | D25: CASTILLO 15*15 cm ACABADO APARENTE, REFORZADO CON 4 VAR #3 Y ESTRIBOS #2 @ 20 cm. INCLUYE: MATERIAL, CIMBRA, MANO DE OBRA, HERRAMIENTA Y EQUIPO. | E25: ml
A26: Concepto | C26: 03-003 | D26: COLUMNA DE 20 X 50 cm ACABADO APARENTE DE CONCRETO F´c=200 kg/cm2 REFORZADA CON 8 VAR 1/2". INCLUYE; MATERIALES, CIMBRA, MANO DE OBRA, HERRAMIENTA Y EQUIPO. | E26: ml
A27: Concepto | C27: 03-004 | D27: DALA DE CERRAMIENTO 16 X 22 cm ACABADO APARENTE, REFORZADO CON 4 VAR #3 Y ESTRIBOS #2 @ 20 cm. INCLUYE; MATERIALES, CIMBRA, MANO DE OBRA, HERRAMIENTA Y EQUIUPO. | E27: ml | F27: =Generadores!I152 -> 5.3
A28: Concepto | C28: 03-005 | D28: VIGA TIPO V1 | E28: ml
A29: Concepto | C29: 03-006 | D29: VIGA TIPO V2 | E29: ml
A30: Subcapítulo | B30: - | C30: #04-000 | D30: LOSA , FIRME Y BANQUETAS.
A31: Concepto | C31: 04-001 | D31: LOSA DE VIGUETA Y DOVELA DE 25 cm DE ESPESOR. INCLUYE; MATERIAL, CIMBRA, MANO DE OBRA, CURADOR, HERRAMIENTA Y EQUIPO. | E31: m²
A32: Concepto | C32: 04-002 | D32: PRETIL DE 1.00 M DE ALTURA EN LOSA DE AZOTEA A BASE DE LARILLO APARENTE. INCLUYE; MATERIALES, MANO DE OBRA Y HERRAMIENTA. PRIMER NIVEL | E32: ml
A33: Concepto | C33: 04-003 | D33: AFINE POR MEDIOS MANUALES PARA RECIBIR PENDIENTES. INCLUYE; MANO DE OBRA Y HERRAMIENTA. | E33: m² | F33: =Generadores!I240+Generadores!I247 -> 20.14
A34: Concepto | C34: 04-004 | D34: GOTERO PARA VOLADO | E34: ml
A35: Subcapítulo | B35: - | C35: #05-000 | D35: ACABADOS PLANTA BAJA
A36: Concepto | C36: 05-002 | D36: APLANADO PARA ACABADO FINO EN INTERIORES A BASE DE YESO DE 2 CM DE ESPESOR EN PLAFONES | E36: m²
A37: Concepto | C37: 05-003 | D37: ENTORTADO DE HASTA 2.5 cm ACABADO PLANEADO PARA RECIBIR PISO CERAMICO, A BASE DE MORTERO ARENA-CEMENTO 1:3. INCLUYE; MATERIAL, MANO DE OBRA Y HERRAMIENTA. | E37: m² | F37: =Generadores!I277 -> 19.91
A38: Concepto | C38: 05-004 | D38: COLOCACIÓN DE PISO DE PORCELANATO, ASENTADO CON ADHESIVO PARA PISO Y EMBOQUILLADO, INCLUYE: MANO DE OBRA, RECORTES Y LIMPIEZA | E38: m² | F38: =Generadores!I285 -> 19.91
A39: Concepto | C39: 05-005 | D39: ZOCLO DE PORCELANATO DE 7.5X60 CM., MARCA INTERCERAMIC ASENTADO CON ADHESIVO PARA PISO Y EMBOQUILLADOR DE COLOR, INCLUYE RECORTES. | E39: ml | F39: =Generadores!I293 -> 6.02
A40: Concepto | C40: 05-006 | D40: PINTURA VINILICA EN MUROS Y PLAFONES MARCA BEREL O SIMILAR EN COLOR BLANCO, INCLUYE: PREPARACION DE LA SUPERFICIE, DOS MANOS DE PINTURA | E40: m² | F40: =Generadores!I303+Generadores!I312 -> 96.9715
...
